Issue {issueClosedAt = Just (GithubDate {fromGithubDate = 2015-10-27 14:06:03 UTC}), issueUpdatedAt = GithubDate {fromGithubDate = 2015-10-27 14:07:21 UTC}, issueEventsUrl = "https://api.github.com/repos/lamby/django-slack/issues/17/events", issueHtmlUrl = Just "https://github.com/lamby/django-slack/issues/17", issueClosedBy = Nothing, issueLabels = [], issueNumber = 17, issueAssignee = Nothing, issueUser = GithubUser {githubOwnerAvatarUrl = "https://avatars.githubusercontent.com/u/3472431?v=3", githubOwnerLogin = "turiphro", githubOwnerUrl = "https://api.github.com/users/turiphro", githubOwnerId = 3472431, githubOwnerGravatarId = Just ""}, issueTitle = "Error on initialisation (Python 3)", issuePullRequest = Nothing, issueUrl = "https://api.github.com/repos/lamby/django-slack/issues/17", issueCreatedAt = GithubDate {fromGithubDate = 2015-10-27 13:58:56 UTC}, issueBody = Just "```\r\nTraceback (most recent call last):\r\n  File \"./manage.py\", line 10, in <module>\r\n    execute_from_command_line(sys.argv)\r\n  File \"/home/ttn-dev/.venv/lib/python3.4/site-packages/django/core/management/__init__.py\", line 338, in execute_from_command_line\r\n    utility.execute()\r\n  File \"/home/ttn-dev/.venv/lib/python3.4/site-packages/django/core/management/__init__.py\", line 312, in execute\r\n    django.setup()\r\n  File \"/home/ttn-dev/.venv/lib/python3.4/site-packages/django/__init__.py\", line 18, in setup\r\n    apps.populate(settings.INSTALLED_APPS)\r\n  File \"/home/ttn-dev/.venv/lib/python3.4/site-packages/django/apps/registry.py\", line 85, in populate\r\n    app_config = AppConfig.create(entry)\r\n  File \"/home/ttn-dev/.venv/lib/python3.4/site-packages/django/apps/config.py\", line 86, in create\r\n    module = import_module(entry)\r\n  File \"/home/ttn-dev/.venv/lib/python3.4/importlib/__init__.py\", line 109, in import_module\r\n    return _bootstrap._gcd_import(name[level:], package, level)\r\n  File \"<frozen importlib._bootstrap>\", line 2254, in _gcd_import\r\n  File \"<frozen importlib._bootstrap>\", line 2237, in _find_and_load\r\n  File \"<frozen importlib._bootstrap>\", line 2226, in _find_and_load_unlocked\r\n  File \"<frozen importlib._bootstrap>\", line 1200, in _load_unlocked\r\n  File \"<frozen importlib._bootstrap>\", line 1129, in _exec\r\n  File \"<frozen importlib._bootstrap>\", line 1471, in exec_module\r\n  File \"<frozen importlib._bootstrap>\", line 321, in _call_with_frames_removed\r\n  File \"/home/ttn-dev/.venv/lib/python3.4/site-packages/django_slack/__init__.py\", line 244, in <module>\r\n    from .api import slack_message\r\n  File \"/home/ttn-dev/.venv/lib/python3.4/site-packages/django_slack/api.py\", line 10, in <module>\r\n    backend = from_dotted_path(app_settings.BACKEND)()\r\n  File \"/home/ttn-dev/.venv/lib/python3.4/site-packages/django_slack/utils.py\", line 16, in from_dotted_path\r\n    return getattr(__import__(module, {}, {}, (attr,)), attr)\r\n  File \"/home/ttn-dev/.venv/lib/python3.4/site-packages/django_slack/backends.py\", line 27\r\n    print \"I: Slack message:\"\r\n                            ^\r\nSyntaxError: Missing parentheses in call to 'print'\r\n```\r\n\r\nLooks like there's some problems with Python 3 support?", issueState = "closed", issueId = 113589265, issueComments = 3, issueMilestone = Nothing}