Issue {issueClosedAt = Just (GithubDate {fromGithubDate = 2015-11-02 10:47:27 UTC}), issueUpdatedAt = GithubDate {fromGithubDate = 2015-11-02 10:47:27 UTC}, issueEventsUrl = "https://api.github.com/repos/lamby/django-slack/issues/18/events", issueHtmlUrl = Just "https://github.com/lamby/django-slack/issues/18", issueClosedBy = Nothing, issueLabels = [], issueNumber = 18, issueAssignee = Nothing, issueUser = GithubUser {githubOwnerAvatarUrl = "https://avatars.githubusercontent.com/u/73378?v=3", githubOwnerLogin = "Eraldo", githubOwnerUrl = "https://api.github.com/users/Eraldo", githubOwnerId = 73378, githubOwnerGravatarId = Just ""}, issueTitle = "Installation exception (Python 3)", issuePullRequest = Nothing, issueUrl = "https://api.github.com/repos/lamby/django-slack/issues/18", issueCreatedAt = GithubDate {fromGithubDate = 2015-11-01 15:16:44 UTC}, issueBody = Just "# Context\r\n\r\nName | Version\r\n---|---\r\nOs | OS X 10.11.1 \r\nAllauth | 0.23.0.final.0\r\nCrispy_Forms | 1.5.2\r\nDebug Toolbar | 1.4\r\nDjango | 1.8.5\r\nDjango_Extensions | 1.5.7\r\nMessage queue | 1.0.0\r\nPython | 3.4.1\r\n\r\n# What I did\r\n`$ pip install django-slack`\r\nAdded `INSTALLED_APPS += ('django_slack', )` to my settings.\r\n`$ ./manage.py runserver`\r\n\r\n# Traceback\r\n```python\r\n...\r\n  File \"/Users/eraldo/.virtualenvs/colegend/lib/python3.4/site-packages/django/apps/registry.py\", line 137, in get_app_configs\r\n    self.check_apps_ready()\r\n  File \"/Users/eraldo/.virtualenvs/colegend/lib/python3.4/site-packages/django/apps/registry.py\", line 124, in check_apps_ready\r\n    raise AppRegistryNotReady(\"Apps aren't loaded yet.\")\r\ndjango.core.exceptions.AppRegistryNotReady: Apps aren't loaded yet.\r\n\r\nProcess finished with exit code 1\r\n```\r\n\r\n# Debugging\r\n\r\nTo find out what went wrong, I did:\r\n```python\r\nimport django_slack\r\n```\r\n \r\nThat got me this trace:\r\n```python\r\n  File \"/Users/eraldo/.virtualenvs/colegend/lib/python3.4/site-packages/django_slack/backends.py\", line 3, in <module>\r\n    import urllib2\r\nImportError: No module named 'urllib2'\r\n```\r\n\r\nSome research later I found the suggested fix:\r\nhttp://stackoverflow.com/questions/2792650/python3-error-import-error-no-module-name-urllib\r\n\r\n# Action\r\n\r\nI would love your app to work with python 3.\r\nI am not used to doing things like pull requests.\r\n\r\nSo Chris, how shall we proceed? :D \r\n\r\nFriendly greetings from Berlin..\r\n*Eraldo*\r\n", issueState = "closed", issueId = 114475077, issueComments = 3, issueMilestone = Nothing}