IssueComment {issueCommentUpdatedAt = GithubDate {fromGithubDate = 2015-10-13 06:44:50 UTC}, issueCommentUser = GithubUser {githubOwnerAvatarUrl = "https://avatars.githubusercontent.com/u/17590?v=3", githubOwnerLogin = "bastianh", githubOwnerUrl = "https://api.github.com/users/bastianh", githubOwnerId = 17590, githubOwnerGravatarId = Just ""}, issueCommentUrl = "https://api.github.com/repos/lamby/django-slack/issues/comments/147620834", issueCommentCreatedAt = GithubDate {fromGithubDate = 2015-10-13 06:44:50 UTC}, issueCommentBody = "hmm.. could not reproduce it using a minimal django project. Looks like the import of the function in __init__.py triggers the loading of something else in my project that is not allowed to load at this point. (some model?). When I uncomment the import in __init__.py and import the function from api.py everything works.\r\nThe traceback is not really helpful :(\r\n```\r\nTraceback (most recent call last):\r\n  File \"./manage.py\", line 10, in <module>\r\n    execute_from_command_line(sys.argv)\r\n  File \"/Users/bastianh/Development/corp_manager/.venv/lib/python2.7/site-packages/django/core/management/__init__.py\", line 350, in execute_from_command_line\r\n    utility.execute()\r\n  File \"/Users/bastianh/Development/corp_manager/.venv/lib/python2.7/site-packages/django/core/management/__init__.py\", line 342, in execute\r\n    self.fetch_command(subcommand).run_from_argv(self.argv)\r\n  File \"/Users/bastianh/Development/corp_manager/.venv/lib/python2.7/site-packages/django/core/management/__init__.py\", line 176, in fetch_command\r\n    commands = get_commands()\r\n  File \"/Users/bastianh/Development/corp_manager/.venv/lib/python2.7/site-packages/django/utils/lru_cache.py\", line 100, in wrapper\r\n    result = user_function(*args, **kwds)\r\n  File \"/Users/bastianh/Development/corp_manager/.venv/lib/python2.7/site-packages/django/core/management/__init__.py\", line 71, in get_commands\r\n    for app_config in reversed(list(apps.get_app_configs())):\r\n  File \"/Users/bastianh/Development/corp_manager/.venv/lib/python2.7/site-packages/django/apps/registry.py\", line 137, in get_app_configs\r\n    self.check_apps_ready()\r\n  File \"/Users/bastianh/Development/corp_manager/.venv/lib/python2.7/site-packages/django/apps/registry.py\", line 124, in check_apps_ready\r\n    raise AppRegistryNotReady(\"Apps aren't loaded yet.\")\r\ndjango.core.exceptions.AppRegistryNotReady: Apps aren't loaded yet.\r\n```", issueCommentId = 147620834}